Workbook

Sheet Summary
A1: RAG Evaluation Report — EU AI Act / GDPR Compliance Assistant
A2: External LLM-as-judge evaluation of 41 test cases · pipeline_outputs_for_external_judge.jsonl
A4: 1. Overall Results (N=41)
A5: Metric | B5: Value | C5: What it measures
A6: Context Recall @5 (doc-level) | B6: ='Per-Item Scores'!F44 -> 0.82926829 | C6: % of queries where the labelled gold document appears anywhere in the top-5 retrieved chunks
A7: Mean Reciprocal Rank (MRR) | B7: ='Per-Item Scores'!H44 -> 0.55975122 | C7: How high the gold document ranks when it is retrieved (1.0 = always rank 1)
A8: Citation Recall (gold doc cited) | B8: ='Per-Item Scores'!I44 -> 0.82926829 | C8: % of queries whose citation list includes the gold document
A9: Faithfulness (avg, judge-scored) | B9: ='Per-Item Scores'!K44 -> 0.95853659 | C9: Is the generated answer grounded in retrieved context (no fabrication)?
A10: Answer Correctness (avg, judge-scored) | B10: ='Per-Item Scores'!L44 -> 0.7804878 | C10: Does the generated answer match the expected answer in substance?
A11: Answer Relevancy | B11: =1 -> 1 | C11: All 41 answers are directly on-topic / address the question asked (none go off-topic) — see note below
A13: 2. Results by Question Difficulty
A14: Difficulty | B14: N | C14: Retrieval Hit@5 | D14: MRR | E14: Citation Recall | F14: Faithfulness | G14: Answer Correctness
A15: single-hop | B15: =COUNTIF('Per-Item Scores'!B2:B42,A15) -> 28 | C15: =AVERAGEIF('Per-Item Scores'!B2:B42,A15,'Per-Item Scores'!F2:F42) -> 0.92857143 | D15: =AVERAGEIF('Per-Item Scores'!B2:B42,A15,'Per-Item Scores'!H2:H42) -> 0.67082857 | E15: =AVERAGEIF('Per-Item Scores'!B2:B42,A15,'Per-Item Scores'!I2:I42) -> 0.92857143 | F15: =AVERAGEIF('Per-Item Scores'!B2:B42,A15,'Per-Item Scores'!K2:K42) -> 1 | G15: =AVERAGEIF('Per-Item Scores'!B2:B42,A15,'Per-Item Scores'!L2:L42) -> 0.85714286
A16: multi-hop | B16: =COUNTIF('Per-Item Scores'!B2:B42,A16) -> 3 | C16: =AVERAGEIF('Per-Item Scores'!B2:B42,A16,'Per-Item Scores'!F2:F42) -> 0.33333333 | D16: =AVERAGEIF('Per-Item Scores'!B2:B42,A16,'Per-Item Scores'!H2:H42) -> 0.16666667 | E16: =AVERAGEIF('Per-Item Scores'!B2:B42,A16,'Per-Item Scores'!I2:I42) -> 0.33333333 | F16: =AVERAGEIF('Per-Item Scores'!B2:B42,A16,'Per-Item Scores'!K2:K42) -> 0.83333333 | G16: =AVERAGEIF('Per-Item Scores'!B2:B42,A16,'Per-Item Scores'!L2:L42) -> 0.43333333
A17: cross-reference | B17: =COUNTIF('Per-Item Scores'!B2:B42,A17) -> 8 | C17: =AVERAGEIF('Per-Item Scores'!B2:B42,A17,'Per-Item Scores'!F2:F42) -> 0.625 | D17: =AVERAGEIF('Per-Item Scores'!B2:B42,A17,'Per-Item Scores'!H2:H42) -> 0.3541625 | E17: =AVERAGEIF('Per-Item Scores'!B2:B42,A17,'Per-Item Scores'!I2:I42) -> 0.625 | F17: =AVERAGEIF('Per-Item Scores'!B2:B42,A17,'Per-Item Scores'!K2:K42) -> 0.85 | G17: =AVERAGEIF('Per-Item Scores'!B2:B42,A17,'Per-Item Scores'!L2:L42) -> 0.74375
A18: temporal-conflict | B18: =COUNTIF('Per-Item Scores'!B2:B42,A18) -> 2 | C18: =AVERAGEIF('Per-Item Scores'!B2:B42,A18,'Per-Item Scores'!F2:F42) -> 1 | D18: =AVERAGEIF('Per-Item Scores'!B2:B42,A18,'Per-Item Scores'!H2:H42) -> 0.41665 | E18: =AVERAGEIF('Per-Item Scores'!B2:B42,A18,'Per-Item Scores'!I2:I42) -> 1 | F18: =AVERAGEIF('Per-Item Scores'!B2:B42,A18,'Per-Item Scores'!K2:K42) -> 1 | G18: =AVERAGEIF('Per-Item Scores'!B2:B42,A18,'Per-Item Scores'!L2:L42) -> 0.375
A19: OVERALL | B19: =SUM(B15:B18) -> 41 | C19: =AVERAGE('Per-Item Scores'!F2:F42) -> 0.82926829 | D19: =AVERAGE('Per-Item Scores'!H2:H42) -> 0.55975122 | E19: =AVERAGE('Per-Item Scores'!I2:I42) -> 0.82926829 | F19: =AVERAGE('Per-Item Scores'!K2:K42) -> 0.95853659 | G19: =AVERAGE('Per-Item Scores'!L2:L42) -> 0.7804878
A21: 3. Outcome Distribution (41 cases)
A22: Outcome label | B22: Count | C22: % of total
A23: Correct | B23: =COUNTIF('Per-Item Scores'!M2:M42,A23) -> 27 | C23: =B23/41 -> 0.65853659
A24: Correct-Partial | B24: =COUNTIF('Per-Item Scores'!M2:M42,A24) -> 1 | C24: =B24/41 -> 0.024390244
A25: Correct-Condensed | B25: =COUNTIF('Per-Item Scores'!M2:M42,A25) -> 1 | C25: =B25/41 -> 0.024390244
A26: Partial | B26: =COUNTIF('Per-Item Scores'!M2:M42,A26) -> 6 | C26: =B26/41 -> 0.14634146
A27: Partial / Incorrect | B27: =COUNTIF('Per-Item Scores'!M2:M42,A27) -> 1 | C27: =B27/41 -> 0.024390244
A28: Abstained-Justified / Task Fail | B28: =COUNTIF('Per-Item Scores'!M2:M42,A28) -> 4 | C28: =B28/41 -> 0.097560976
A29: Incorrect / Hallucinated | B29: =COUNTIF('Per-Item Scores'!M2:M42,A29) -> 1 | C29: =B29/41 -> 0.024390244
A30: Total | B30: =SUM(B23:B29) -> 41 | C30: =SUM(C23:C29) -> 1
A32: 4. Key Findings
A33: Finding 1 — Citations are not an independent signal.
A34: In 41/41 records, the 'citations' list is exactly the set of unique document paths in the top-5 retrieved chunks — no more, no less. The pipeline does not currently select which sources actually support the answer; it echoes back whatever was retrieved. Citation accuracy therefore cannot be evaluated as a generation-quality metric on this dataset, and (more importantly) end users cannot trust a citation as evidence a specific claim is grounded. Recommendation: implement claim-level citation attribution.
A36: Finding 2 — Document-level retrieval hit-rate overstates true recall.
A37: Two verified cases (#1, #26) retrieved the correct SOURCE DOCUMENT but the wrong CHUNK within it — the specific sentence needed (a compliance date; a 5-business-day SLA) sat in a different chunk of the same document that wasn't fetched. Both cases are counted as retrieval 'hits' at the document level, but the task still failed. This is the single largest driver of the gap between an 85% document-level hit-rate and a 79% answer-correctness rate. Recommendation: report a chunk-level recall metric, not just a document-level one; consider smaller/overlapping chunks or a second-pass re-ranker for these long guidance pages.
A39: Finding 3 — One clear hallucination under good retrieval (#35).
A40: The gold answer (GDPR Art. 9's 'without prejudice' clause) was present verbatim in TWO retrieved chunks (rank 3 and rank 4/5), yet the model instead built a fluent, well-formatted, but incorrect answer around a different regulation (the Law Enforcement Directive 2016/680, mislabelled 'Biometric Data Directive') and never mentioned GDPR Art. 9. This is the most consequential single error in the set: confident, plausible, and wrong, on a legal cross-reference question a compliance user would rely on directly.
A42: Finding 4 — Self-inconsistency across near-duplicate questions (#38 vs #39).
A43: Asked essentially the same fact two different ways, the system correctly cited Art. 53(2) as the source of the open-source exemption in #38, then in #39 claimed the exemption is 'set out in Article 53(1)(a) and (b) itself' — contradicting its own prior answer. This points to a lack of self-consistency / verification step in generation, worth adding as a dedicated consistency check across paraphrased queries.
A45: Finding 5 — Multi-hop and cross-reference questions are materially weaker than single-hop.
A46: Single-hop correctness averages ~0.86 vs ~0.43 (multi-hop, n=3) and ~0.74 (cross-reference, n=8); single-hop retrieval hit-rate is ~93% vs ~33-67% for the harder categories. The system is reliable on direct lookups but degrades on questions that require connecting two provisions or two documents (e.g. AI Act + GDPR) — exactly where a compliance user needs it most.
A48: Finding 6 — Even on 'hits', completeness often lags.
... A55: 5. Metric Glossary
...

Sheet Per-Item Scores
A1: ID | B1: Difficulty | C1: Question | D1: Expected Answer | E1: Generated Answer | F1: Retrieval Hit@5 (gold doc) | G1: Retrieval Rank | H1: MRR | I1: Citation Includes Gold Doc | J1: # Citations | K1: Faithfulness (0-1) | L1: Answer Correctness (0-1) | M1: Outcome Label | N1: Judge Notes / Rationale
A2: 0 | B2: temporal-conflict | C2: When do Annex III high-risk AI system obligations become applicable? | D2: 2 December 2027, per the Digital Omnibus amendment to Article 113's third paragraph, point (c) — not the original 2 August 2026 date (the Regulation's general application date) that applied before the amendment. | E2: The obligations for high‑risk AI systems that are listed in **Annex III** become applicable from **2 December 2027**. This is the date set for the application of Sections 1, 2 and 3 of Chapter III of Regulation (EU) 2024/1689 for AI systems classified as high‑risk pursuant to Article 6(2) and Annex III. | F2: 1 | G2: 3 | H2: 0.3333 | I2: 1 | J2: 5 | K2: 1 | L2: 0.75 | M2: Correct-Partial | N2: Correct date (2 Dec 2027), verified grounded in retrieved chunk (rank 3, digital_omnibus doc). But doesn't flag that this date supersedes the original 2 Aug 2026 date -- the core point a temporal-conflict test checks.
A3: 1 | B3: temporal-conflict | C3: By what date must AI systems classified as high-risk under Article 6(1) and Annex I (i.e. safety components of products already covered by other EU product-safety legislation) comply with the AI Act's high-risk requirements? | D3: 2 August 2028, per the Digital Omnibus amendment. The original Regulation set this date at 2 August 2027 (Article 113, third paragraph, original point (c)). | E3: The provided excerpts do not contain a specific date by which AI systems classified as high‑risk under Article 6(1) and Annex I must comply with the AI Act’s high‑risk requirements. | F3: 1 | G3: 2 | H3: 0.5 | I3: 1 | J3: 5 | K3: 1 | L3: 0 | M3: Abstained-Justified / Task Fail | N3: VERIFIED: the correct fact ('2 August 2028') sits in the SAME source document, chunk_idx 28 -- which WAS retrieved for record 0's query. For this query the retriever instead fetched chunk_idx 17 of that doc (grace-period text), which does not contain the date. Model correctly avoided hallucinating given what it saw, but the task failed due to a chunk-level retrieval miss hidden inside a document-level hit.
A4: 2 | B4: single-hop | C4: What was the original application date for the AI Act's high-risk system requirements (Chapter III), before the Digital Omnibus amendment? | D4: 2 August 2026 — the Regulation's general application date set in the original Article 113 ('It shall apply from 2 August 2026'), which covered Annex III high-risk systems since they had no separate carve-out in the original text. Only Article 6(1)/Annex I systems had a later original date of 2 August 2027. | E4: The provided excerpts do not contain information about the original application date for the AI Act’s high‑risk system requirements (Chapter III) before the Digital Omnibus amendment. | F4: 0 | H4: 0 | I4: 0 | J4: 5 | K4: 1 | L4: 0 | M4: Abstained-Justified / Task Fail | N4: Full document-level retrieval miss -- correct, honest abstention.
A5: 3 | B5: single-hop | C5: When do the new prohibited AI practices added by the Digital Omnibus (the new points (ba) and (bb) inserted into Article 5(1), and new paragraphs 5(1a) and 5(1b)) become applicable? | D5: 2 December 2026. | E5: The new prohibited AI practices that were added by the Digital Omnibus – namely the new points **(ba)** and **(bb)** inserted into Article 5(1), and the new paragraphs **5(1a)** and **5(1b)** – become applicable from **2 December 2026**. | F5: 1 | G5: 2 | H5: 0.5 | I5: 1 | J5: 3 | K5: 1 | L5: 1 | M5: Correct | N5: Exact match, well grounded (rank 2).
A6: 4 | B6: multi-hop | C6: Does the Digital Omnibus change when Chapters I and II of the AI Act apply? | D6: No — Chapters I and II still apply from 2 February 2025, the same as in the original Regulation. The Omnibus only adds an exception for the new prohibited-practice provisions (Article 5(1) points (ba)/(bb) and Article 5(1a)/(1b)), which apply later, from 2 December 2026. | E6: The context provided does not indicate that the Digital Omnibus changes the date on which Chapters I and II of the AI Act apply. According to Article 113 of the AI Act, Chapters I and II are set to apply from 2 February 2025, and there is no mention in the excerpts that the Digital Omnibus alters this schedule. | F6: 0 | H6: 0 | I6: 0 | J6: 5 | K6: 1 | L6: 0.5 | M6: Partial | N6: Gets the primary question right (Ch I/II unaffected, 2 Feb 2025) but misses the multi-hop link to the new prohibited-practice exception (2 Dec 2026); Digital Omnibus doc was not retrieved.
A7: 5 | B7: single-hop | C7: According to the Digital Omnibus amendment, from what date do Articles 102 to 110 of the AI Act apply? | D7: 27 July 2026. | E7: The provided context excerpts do not contain information about the dates on which Articles 102 to 110 of the AI Act apply under the Digital Omnibus amendment. | F7: 0 | H7: 0 | I7: 0 | J7: 5 | K7: 1 | L7: 0 | M7: Abstained-Justified / Task Fail | N7: Full document-level retrieval miss -- correct, honest abstention.
A8: 6 | B8: single-hop | C8: According to the AI Act's definitions in Article 3, what does 'reasonably foreseeable misuse' mean? | D8: The use of an AI system in a way that is not in accordance with its intended purpose, but which may result from reasonably foreseeable human behaviour or interaction with other systems, including other AI systems. | E8: According to the AI Act’s definitions in Article 3, “reasonably foreseeable misuse” means the use of an AI system in a way that is not in accordance with its intended purpose, but which may result from reasonably foreseeable human behaviour or interaction with other systems, including other AI systems. | F8: 1 | G8: 1 | H8: 1 | I8: 1 | J8: 4 | K8: 1 | L8: 1 | M8: Correct | N8: Verbatim-correct definition, rank 1.
A9: 7 | B9: single-hop | C9: Under Article 5 of the AI Act, is real-time remote biometric identification in publicly accessible spaces for law enforcement completely banned? | D9: No. It is prohibited by default, but the AI Act allows narrow exceptions where strictly necessary for: (i) targeted searches for victims of abduction, trafficking, or sexual exploitation, or missing persons; (ii) prevention of a specific, substantial and imminent threat to life or physical safety, or a genuine terrorist threat; or (iii) localising/identifying a suspect for prosecuting certain serious crimes carrying at least a 4-year custodial sentence. Even then, use requires a fundamental rights impact assessment, EU database registration, and generally prior judicial or independent administrative authorisation. | E9: No. Article 5 of the AI Act does **not** ban real‑time remote biometric identification in publicly accessible spaces for law enforcement. Instead, it sets out a detailed regulatory framework that allows such use only under strict conditions (e.g., prior authorisation, fundamental‑rights impact assessment, registration in the EU database, and compliance with biometric‑data rules). The Act therefore regulates rather than prohibits this type of system. | F9: 1 | G9: 2 | H9: 0.5 | I9: 1 | J9: 2 | K9: 1 | L9: 0.6 | M9: Partial | N9: Right stance (not a full ban) but omits the three specific statutory exception categories that carry the substance of the answer. Retrieval succeeded (rank 2) -- an extraction/completeness gap, not a retrieval gap.
A10: 8 | B10: single-hop | C10: Under Article 6(3) of the AI Act, can an AI system listed in Annex III avoid being classified as high-risk? | D10: Yes, by derogation, an Annex III system is not considered high-risk if it does not pose a significant risk of harm to health, safety, or fundamental rights, including by not materially influencing the outcome of decision-making — for example if it performs a narrow procedural task, improves the result of a previously completed human activity, detects deviations from prior human decision-making patterns without replacing human assessment, or performs a preparatory task. However, this derogation never applies if the system performs profiling of natural persons — such a system is always considered high-risk. | E10: Yes. Article 6(3) states that an AI system referred to in Annex III **shall not be considered high‑risk** where it does not pose a significant risk of harm to the health, safety or fundamental rights of natural persons, **including by not materially influencing the outcome of decision making**. The paragraph then lists conditions that, if met, allow the system to be exempted: * (a) the AI system is intended to perform a narrow procedural task; * (b) the AI system is intended to improve the result of a previously completed human activity; * (c) the AI system is intended to detect decision‑making patterns or deviations from prior decision‑making patterns and is not meant to replace or influence the previously completed human assessment, without proper human review; or * (d) the AI system is intended to perform a preparatory task to an assessment relevant for the purposes of the use cases listed in Annex III. If any of these conditions are satisfied, the system can avoid being classified as high‑risk, provided it also does not perform profiling of natural persons (which would automatically make it high‑risk). | F10: 1 | G10: 1 | H10: 1 | I10: 1 | J10: 2 | K10: 1 | L10: 1 | M10: Correct | N10: Complete, well-structured, rank 1.
A11: 9 | B11: single-hop | C11: Under Article 9 of the AI Act, is the risk management system for a high-risk AI system a one-time exercise done before market placement? | D11: No. It must be established, implemented, documented and maintained as a continuous iterative process planned and run throughout the entire lifecycle of the high-risk AI system, requiring regular systematic review and updating. | E11: No. Article 9 of the AI Act requires that a risk‑management system for a high‑risk AI system be **established, implemented, documented and maintained** throughout the entire lifecycle of the system. It is described as a continuous, iterative process that is regularly reviewed and updated, and testing may be performed at any time during development and prior to market placement. Thus, it is not a one‑time exercise done only before market placement. | F11: 1 | G11: 1 | H11: 1 | I11: 1 | J11: 3 | K11: 1 | L11: 1 | M11: Correct | N11: Complete, rank 1.
A12: 10 | B12: single-hop | C12: Under Article 10 of the AI Act, can a provider of a high-risk AI system ever process special categories of personal data (e.g. race, health data) to detect and correct bias? | D12: Yes, exceptionally, but only if strictly necessary for bias detection and correction, and only when several conditions are all met: the correction cannot be effectively achieved with other data (including synthetic or anonymised data); the special category data is subject to technical limitations on re-use and state-of-the-art security/privacy measures including pseudonymisation; strict access controls and documentation are in place; the data is not transmitted or otherwise accessed by other parties; it is deleted once the bias is corrected or the retention period ends, whichever is first; and the records of processing document why this was strictly necessary. | E12: Yes. Under Article 10 of the AI Act, a provider of a high‑risk AI system may **exceptionally** process special categories of personal data (such as race or health data) **if and only if** it is strictly necessary to detect and correct bias. The processing must be carried out under the safeguards and conditions set out in the regulation (e.g., technical limitations, security measures, deletion after bias correction, documentation of necessity, etc.). | F12: 1 | G12: 5 | H12: 0.2 | I12: 1 | J12: 3 | K12: 1 | L12: 0.8 | M12: Correct-Condensed | N12: Correct gist; several safeguards condensed into 'etc.'. Retrieved at rank 5 -- weak ranking even though technically a hit.
A13: 11 | B13: single-hop | C13: Under Article 11 of the AI Act, do small and medium-sized enterprises get any relief from the technical documentation requirements for high-risk AI systems? | D13: Yes. SMEs, including start-ups, may provide the Annex IV technical documentation elements in a simplified manner, using a simplified technical documentation form that the Commission must establish targeted at the needs of small and microenterprises. Notified bodies are required to accept this simplified form for conformity assessment purposes. | E13: Yes. Under Article 11 of the AI Act, small and medium‑sized enterprises (SMEs) and start‑ups are allowed to provide the technical documentation for a high‑risk AI system in a **simplified manner**. The Commission will provide a simplified technical documentation form that SMEs can use, and notified bodies must accept this form for the conformity assessment. This is a specific relief from the full technical documentation requirements that apply to larger operators. | F13: 1 | G13: 3 | H13: 0.3333 | I13: 1 | J13: 3 | K13: 1 | L13: 1 | M13: Correct | N13: Complete match, rank 3.
A14: 12 | B14: single-hop | C14: Under Article 12 of the AI Act, what minimum logging information must a high-risk remote biometric identification system record? | D14: At minimum: the period of each use of the system (start and end date/time), the reference database against which input data was checked, the input data for which the search led to a match, and the identification of the natural persons who verified the results (as referred to in Article 14(5)). | E14: Under Article 12 of the AI Act, a high‑risk remote biometric identification system must automatically record, at a minimum: 1. **The period of each use** – the start date and time and the end date and time of every use of the system. 2. **The reference database** – the database against which the input data were checked. 3. **The input data that led to a match** – the specific data that caused the system to find a match. 4. **The identification of the natural persons involved in the verification of the results** – the individuals who verified the system’s output. | F14: 1 | G14: 1 | H14: 1 | I14: 1 | J14: 2 | K14: 1 | L14: 1 | M14: Correct | N14: Complete, rank 1.
A15: 13 | B15: single-hop | C15: Under Article 13 of the AI Act, what must the instructions for use of a high-risk AI system contain regarding accuracy? | D15: The instructions must state the level of accuracy, including its metrics, robustness and cybersecurity against which the system has been tested and validated and which can be expected, plus any known or foreseeable circumstances that could affect that expected level of accuracy, robustness and cybersecurity. | E15: Under Article 13 of the AI Act, the instructions for use of a high‑risk AI system must include: * **The level of accuracy** of the system, together with the **accuracy metrics** that were used to test and validate it. * The **robustness** and **cybersecurity** levels that the system has been tested against and that can be expected. * Any **known or foreseeable circumstances** that may affect that expected level of accuracy, robustness or cybersecurity. These details are required so that deployers can understand the performance expectations of the system. | F15: 1 | G15: 3 | H15: 0.3333 | I15: 1 | J15: 3 | K15: 1 | L15: 1 | M15: Correct | N15: Complete, rank 3.
A16: 14 | B16: single-hop | C16: Under Article 14 of the AI Act, for high-risk remote biometric identification systems used for identification (Annex III point 1(a)), how many people must verify a match before a deployer acts on it? | D16: At least two natural persons with the necessary competence, training and authority must separately verify and confirm the identification before the deployer takes any action or decision based on it — unless the system is used for law enforcement, migration, border control or asylum purposes where national or Union law considers this requirement disproportionate. | E16: Under Article 14 of the AI Act, for high‑risk remote biometric identification systems used for identification (Annex III point 1(a)), a match must be separately verified and confirmed by **at least two natural persons** before a deployer may act on it. | F16: 1 | G16: 1 | H16: 1 | I16: 1 | J16: 2 | K16: 1 | L16: 0.7 | M16: Partial | N16: Gets the 'two person' rule right but omits the law-enforcement/migration/border/asylum exception. Retrieval succeeded (rank 1) -- extraction/completeness gap.
A17: 15 | B17: single-hop | C17: Under Article 15 of the AI Act, what specific cybersecurity threats must high-risk AI systems' technical solutions address, where appropriate? | D17: Measures to prevent, detect, respond to, resolve and control attacks trying to manipulate the training data set (data poisoning), pre-trained components used in training (model poisoning), inputs designed to cause the AI model to make a mistake (adversarial examples or model evasion), confidentiality attacks, or model flaws. | E17: Under Article 15, the technical solutions that high‑risk AI systems must implement “shall include, where appropriate, measures to prevent, detect, respond to, resolve and control for attacks trying to manipulate the training data set (data poisoning), or pre‑trained components used in training (model poisoning), inputs designed to cause the AI model to make a mistake (adversarial examples or model evasion), confidentiality attacks or model flaws.” | F17: 1 | G17: 1 | H17: 1 | I17: 1 | J17: 2 | K17: 1 | L17: 1 | M17: Correct | N17: Exact quote match, rank 1.
A18: 16 | B18: single-hop | C18: Under Article 16 of the AI Act, besides ensuring compliance with the Section 2 requirements, what conformity-related steps must a provider of a high-risk AI system complete before placing it on the market? | D18: The provider must have a quality management system in place, ensure the system undergoes the relevant conformity assessment procedure, draw up an EU declaration of conformity, and affix the CE marking (or place it on packaging/documentation if not possible on the system itself), in addition to keeping required documentation and logs and complying with registration obligations. | E18: Under Article 16 of the AI Act, a provider of a high‑risk AI system must, **in addition to ensuring that the system complies with the requirements set out in Section 2**, complete the following conformity‑related steps before the system can be placed on the market: | Step | What the provider must do | |------|---------------------------| | **(f) Conformity assessment** | Make sure the system undergoes the relevant conformity‑assessment procedure referred to in Article 43 (e.g., internal control or a notified‑body assessment, depending on the system). | | **(g) EU declaration of conformity** | Draw up an EU declaration of conformity in accordance with Article 47. | | **(h) CE marking** | Affix the CE marking to the system (or to its packaging or accompanying documentation) to indicate conformity with the Regulation, in accordance with Article 48. | | **(i) Registration** | Comply with the registration obligations referred to in Article 49(1). | | **(j) Corrective actions** | Take the necessary corrective actions and provide information as required in Article 20. | | **(k) Demonstrate compliance** | Upon a reasoned request of a national competent authority, demonstrate the conformity of the high‑risk AI system with the requirements set out in Section 2. | | **(l) Accessibility** | Ensure that the system complies with accessibility requirements in accordance with Directives (EU) 2016/2102 and (EU) 2019/882. | These steps, together with the other obligations listed in Article 16 (e.g., having a quality‑management system, keeping documentation and logs, indicating contact details, etc.), must be fulfilled before the provider can place the high‑risk AI system on the market. | F18: 1 | G18: 3 | H18: 0.3333 | I18: 1 | J18: 2 | K18: 1 | L18: 1 | M18: Correct | N18: Thorough, exceeds expected detail with correctly-grounded extras, rank 4.
A19: 17 | B19: single-hop | C19: Under Article 50 of the AI Act, if an AI-generated deepfake forms part of an evidently satirical or artistic work, is the deployer still required to disclose that the content is AI-generated? | D19: Yes, but the obligation is limited: the deployer only needs to disclose the existence of the generated or manipulated content in an appropriate manner that does not hamper the display or enjoyment of the work — a full, prominent disclosure isn't required in that context. | E19: Yes. Under Article 50(4) of the AI Act, a deployer must disclose that content has been artificially generated or manipulated **even when it is part of an evidently artistic, creative, satirical, fictional or analogous work**. The disclosure is limited to stating the existence of the AI‑generated or manipulated content in an appropriate manner that does not hamper the display or enjoyment of the work (see guidance excerpts [3] and [4]). | F19: 1 | G19: 4 | H19: 0.25 | I19: 1 | J19: 3 | K19: 1 | L19: 1 | M19: Correct | N19: Complete match, rank 4.
... A32: 30 | B32: single-hop | C32: According to the (second draft) Code of Practice on Transparency of AI-Generated Content, why do the drafters say a single active marking technique is not enough to meet Article 50(2)'s requirements? | D32: Because, as of drafting, no single active marking technique suffices to meet all four requirements of Article 50(2) AI Act at once — effectiveness, interoperability, robustness and reliability — which is why the Code calls for a multi-layered approach to technical marking solutions, which the drafters describe as the principal recognised way to reasonably comply with those four requirements. | E32: The drafters state that, at the time the Code was drafted, **no single active marking technique is sufficient to satisfy all four requirements of Article 50(2) of the AI Act**—effectiveness, interoperability, robustness, and reliability. Therefore, a multi‑layered approach, combining at least two machine‑readable marking techniques, is required to meet those requirements. This is explicitly mentioned in the excerpts from the Code of Practice, where it is noted that a multi‑layered marking approach is the “principal way of enabling reasonable compliance” with the four requirements. | F32: 1 | G32: 1 | H32: 1 | I32: 1 | J32: 2 | K32: 1 | L32: 1 | M32: Correct | N32: VERIFIED: 'at least two layers of machine-readable active marking' appears verbatim in the top-ranked chunk. Fully grounded, rank 1.
A33: 31 | B33: cross-reference | C33: If a company builds an AI-powered CV-screening tool that processes candidates' employment history and health-related disability accommodation notes to shortlist applicants, would this system trigger GDPR obligations in addition to the AI Act? | D33: Yes. The CV data (employment history, contact details) is 'personal data' under GDPR Article 4(1), and any disability-related information would be 'data concerning health', a special category of personal data whose processing is prohibited under Article 9(1) unless a specific exception in Article 9(2) applies (e.g. explicit consent). Separately, this is also a high-risk AI system under the AI Act (employment/recruitment use case), so both regimes apply cumulatively — GDPR governs the lawfulness of processing the personal/special-category data, while the AI Act governs the AI system's risk management, data governance, and transparency obligations. | E33: The excerpts state that the AI Act does **not** replace or remove the obligations that already exist under Union data‑protection law. In particular, the AI Act “does not affect the obligations of providers and deployers of AI systems in their role as data controllers or processors stemming from Union or national law on the protection of personal data” (see excerpt [4]). Because the CV‑screening tool processes personal data that is directly related to candidates (employment history, health‑related disability accommodation notes, etc.), the company would be a data controller (or processor) under the GDPR. Therefore, in addition to any obligations that arise under the AI Act, the company would also have to comply with the GDPR’s requirements for lawful processing, transparency, data subject rights, data protection impact assessments, and so on. | F33: 0 | H33: 0 | I33: 0 | J33: 3 | K33: 0.8 | L33: 0.5 | M33: Partial | N33: Correct top-level 'Yes, GDPR applies cumulatively' but misses the special-category/Article 9 health-data analysis and the AI Act high-risk employment classification the question specifically probes. Document-level retrieval miss.
A34: 32 | B34: cross-reference | C34: Does GDPR give a data subject any rights specifically about being subject to a fully automated hiring or credit-scoring decision made by an AI system? | D34: Yes. Article 22(1) GDPR gives the data subject the right not to be subject to a decision based solely on automated processing (including profiling) that produces legal effects or similarly significantly affects them, unless it falls under a listed exception (necessary for a contract, authorised by law with safeguards, or based on explicit consent). Where an exception applies, the controller must still implement safeguards, at minimum the right to obtain human intervention, to express a view, and to contest the decision (Article 22(3)). | E34: Yes. According to the GDPR (see § 22 in the provided excerpts), a data subject has the right **not to be subject to a decision that is based solely on automated processing and that produces legal effects or significantly affects them**. This includes decisions such as automated hiring or credit‑scoring that rely only on an AI system without any human intervention. | F34: 1 | G34: 4 | H34: 0.25 | I34: 1 | J34: 3 | K34: 1 | L34: 0.6 | M34: Partial | N34: Correct on Art 22(1) core right; omits Art 22(2) exceptions and Art 22(3) safeguards despite good retrieval (rank 1) -- extraction/completeness gap.
A35: 33 | B35: cross-reference | C35: Does deploying a high-risk AI system that does systematic, large-scale profiling of individuals require a GDPR Data Protection Impact Assessment (DPIA), separately from any AI Act obligations? | D35: Yes. Article 35(1) and (3)(a) GDPR require a DPIA prior to processing where a type of processing, in particular one using new technologies, is likely to result in a high risk to individuals' rights and freedoms — explicitly including a systematic and extensive evaluation of personal aspects based on automated processing, including profiling, that produces legal or similarly significant effects. This DPIA obligation exists independently of, and in addition to, the AI Act's own risk-management and conformity-assessment requirements for high-risk AI systems. | E35: Yes. According to the GDPR excerpts (see source [1] and source [3]), a data protection impact assessment (DPIA) is required **prior to processing** when the processing is likely to result in a high risk to the rights and freedoms of data subjects. The GDPR specifically lists “a systematic and extensive evaluation of personal aspects relating to natural persons which is based on automated processing, including profiling, and on which decisions are based that produce legal effects concerning the natural person” as a situation that triggers a DPIA (source [3] § 3.3 c). Therefore, deploying a high‑risk AI system that performs systematic, large‑scale profiling of individuals constitutes a processing activity that must be accompanied by a GDPR DPIA. This requirement is independent of any obligations under the EU AI Act; the AI Act imposes its own fundamental‑rights impact assessment, but the GDPR still requires a separate DPIA for the high‑risk profiling activity. | F35: 1 | G35: 1 | H35: 1 | I35: 1 | J35: 3 | K35: 1 | L35: 1 | M35: Correct | N35: Well-reasoned cross-document synthesis, rank 1.
A36: 34 | B36: cross-reference | C36: If an AI system used in recruitment processed special categories of personal data (e.g. data revealing racial or ethnic origin) to detect and correct algorithmic bias, is this permitted under GDPR on its own, or does something else need to apply? | D36: Processing special categories of personal data is prohibited by default under GDPR Article 9(1) unless one of the Article 9(2) exceptions applies (such as explicit consent). Separately, the AI Act's Article 10(5) creates a specific, narrow legal basis allowing providers of high-risk AI systems to process such special category data for bias detection and correction, but only where several strict conditions are all met (no viable alternative, technical/organisational safeguards, no third-party access, deletion once bias corrected, documented necessity) — and this is stated to apply 'in addition to' GDPR, not instead of it. | E36: Under the GDPR alone, the processing of special categories of personal data (such as data revealing racial or ethnic origin) is **not** permitted without a specific legal basis and without meeting the strict safeguards that the GDPR requires for special categories. The GDPR (Regulation (EU) 2016/679) allows processing of special categories only if one of the specific conditions in Article 9 applies, and even then the processing must be accompanied by appropriate safeguards (e.g., pseudonymisation, strict access controls, deletion after use, etc.). In the context of a high‑risk AI system used for recruitment, the GDPR by itself does **not** provide a blanket exception for using such data to detect and correct algorithmic bias. The AI Act (Regulation (EU) 2024/1689) introduces an **exceptional legal basis** that permits the processing of special categories of personal data *only when* it is strictly necessary for bias detection and correction, and only if all the conditions and safeguards listed in Article 10(5) (and the related provisions in Article 5) are met. Therefore, to process racial or ethnic origin data for bias detection and correction in a recruitment AI system, you would need to rely on the AI Act’s exceptional legal basis (or another specific GDPR exception that applies) and ensure that all the required safeguards and conditions are satisfied. | F36: 0 | H36: 0 | I36: 0 | J36: 3 | K36: 1 | L36: 0.85 | M36: Correct | N36: Solid synthesis despite a document-level 'miss' on the labelled expected source -- the needed info was available via other retrieved chunks. Shows doc-level recall can understate real answer quality.
A37: 35 | B37: cross-reference | C37: Article 5(1)(h) of the AI Act prohibits real-time remote biometric identification in public spaces for law enforcement except in narrow cases. How does this provision interact with GDPR's rules on biometric data processing? | D37: Article 5(1) of the AI Act itself states that the prohibition (and its law-enforcement exceptions) is 'without prejudice to Article 9 of Regulation (EU) 2016/679 for the processing of biometric data for purposes other than law enforcement' — meaning GDPR's Article 9 special-category rules (which classify biometric data used for unique identification as a prohibited category absent an Article 9(2) exception) continue to apply in parallel wherever the processing isn't for law enforcement purposes covered by the AI Act's own carve-out. | E37: The AI Act’s Article 5(1)(h) sets a very specific, narrow exception for the use of real‑time remote biometric identification (R‑RBI) systems in publicly accessible spaces for law‑enforcement purposes. The provision itself does not create a new legal basis for processing biometric data; instead, it explicitly states that any such use must still be carried out **in accordance with the rules on biometric data processing set out in Directive (​EU) 2016/680** (the “Biometric Data Directive”) and, where applicable, **in accordance with the GDPR (Regulation (​EU) 2016/679)**. Key points from the excerpts: | What the AI Act says | How it interacts with GDPR / Biometric Data Directive | |----------------------|--------------------------------------------------------| | **Article 5(1)(h) limits R‑RBI to very narrow law‑enforcement objectives** | The AI Act does **not** provide a new legal basis for processing biometric data. The processing must still comply with the GDPR’s principles (lawfulness, fairness, transparency, purpose limitation, accuracy, storage limitation) and the specific safeguards of the Biometric Data Directive. | | **Use of R‑RBI must be “strictly necessary” and subject to “appropriate safeguards”** | This mirrors the Biometric Data Directive’s requirement that biometric data may only be processed where strictly necessary, with safeguards for the rights and freedoms of the data subject, and only when authorised by Union or Member‑State law. | | **Fundamental‑rights impact assessment (Article 27) and registration in the EU database (Article 49)** | These steps are additional safeguards that complement the GDPR’s accountability and transparency obligations. | | **Prior authorisation by a judicial or independent administrative authority** | This requirement is a procedural safeguard that aligns with the GDPR’s emphasis on lawful basis and accountability. | In short, Article 5(1)(h) does **not** override or replace GDPR rules on biometric data processing. It merely adds a specific, narrowly defined exception for law‑enforcement use of R‑RBI systems, and it requires that such use still be fully compliant with the GDPR and the Biometric Data Directive’s stringent safeguards. | F37: 1 | G37: 4 | H37: 0.25 | I37: 1 | J37: 2 | K37: 0 | L37: 0 | M37: Incorrect / Hallucinated | N37: MAJOR FINDING (verified against full chunk text): fabricates a framing around 'Directive 2016/680' as the 'Biometric Data Directive' and never surfaces the correct answer -- GDPR Art. 9's 'without prejudice' clause -- despite that exact clause appearing verbatim in TWO retrieved chunks (rank 3 of the AI Act doc, and rank 4/5 of the expected source). Confident, well-formatted, and substantively wrong; a textbook low-faithfulness case with good context available.
A38: 36 | B38: cross-reference | C38: The AI Act Service Desk's summary of Article 113 says the Regulation 'shall apply from 2 August 2026', with earlier dates for certain chapters. Does the AI Act's own primary regulatory text (not just the Service Desk summary) confirm this same set of staggered dates? | D38: Yes. The primary EUR-Lex text of Regulation (EU) 2024/1689, Article 113, matches the Service Desk summary exactly: the Regulation enters into force 20 days after publication, applies generally from 2 August 2026, except Chapters I and II apply from 2 February 2025, Chapter III Section 4 / Chapter V / Chapter VII / Chapter XII and Article 78 apply from 2 August 2025 (except Article 101), and Article 6(1) with its corresponding obligations applies from 2 August 2027. | E38: Yes. The primary regulatory text of the AI Act itself contains the same staggered entry‑into‑force dates that the Service Desk summary cites. * **Article 113 of the Regulation (EU 2024/1689)** – “This Regulation shall enter into force on the twentieth day following that of its publication in the Official Journal of the European Union. It shall apply from 2 August 2026. However: (a) Chapters I and II shall apply from 2 February 2025; (b) Chapter III Section 4, Chapter V, Chapter VII and Chapter XII and Article 78 shall apply from 2 August 2025, with the exception of Article 101; (c) Article 6(1) and the corresponding obligations in this Regulation shall apply from 2 August 2027.” These provisions are part of the official text of the Regulation (source [1]), confirming the staggered dates that the Service Desk summary also reports. | F38: 1 | G38: 3 | H38: 0.3333 | I38: 1 | J38: 4 | K38: 1 | L38: 1 | M38: Correct | N38: Verbatim primary-text quote, fully consistent, rank 3.
A39: 37 | B39: cross-reference | C39: Article 53(1)(d) of the AI Act requires GPAI providers to publish a training-data-content summary 'according to a template provided by the AI Office.' Does the GPAI Code of Practice's Transparency Chapter clarify how this training-content-summary obligation relates to the more detailed Model Documentation Signatories must keep? | D39: Yes. The Transparency Chapter notes that some of the information documented in the (non-public) Model Documentation under Measure 1.1 may also be required, in summarised form, as part of the separate publicly available training-content summary required under Article 53(1)(d) — i.e. the two obligations are related but distinct: full documentation goes to the AI Office/downstream providers on request, while a summarised, public-facing version covers the training-content-summary duty. | E39: The Transparency Chapter does **not** replace the requirement to keep a detailed Model Documentation Form. Instead, it states that the information contained in the Model Documentation can be used **in a summarized form** for the public‑facing “training‑data‑content summary” that providers must publish under Article 53(1)(d). In other words: * **Model Documentation** – a comprehensive, up‑to‑date record (the Model Documentation Form) that must be kept by the provider and supplied to downstream providers and the AI Office when requested. * **Training‑data‑content summary** – a separate, publicly available summary that follows a template supplied by the AI Office. The Transparency Chapter indicates that this summary may draw on the same underlying information that is in the Model Documentation, but it is a distinct, more concise, public disclosure. So the Chapter clarifies that the two obligations are complementary: the detailed documentation is kept for compliance and regulatory purposes, while the summary is a public, template‑based disclosure that can be derived from that documentation. | F39: 1 | G39: 1 | H39: 1 | I39: 1 | J39: 3 | K39: 1 | L39: 1 | M39: Correct | N39: Good cross-document synthesis, rank 1.
A40: 38 | B40: cross-reference | C40: The AI Act Service Desk's Article 53 page mentions that open-source GPAI providers are exempt from Article 53(1)(a) and (b) unless the model has systemic risk. Where in the primary AI Act regulation text is this exception actually written, and does it match the Service Desk's summary? | D40: Yes, it matches. Article 53(2) of the primary AI Act text (also present verbatim in the EUR-Lex source) states that the obligations in Article 53(1) points (a) and (b) do not apply to providers of AI models released under a free and open-source licence that allows access, usage, modification and distribution, and whose parameters (including weights), architecture information, and usage information are publicly available — and explicitly states this exception does not apply to general-purpose AI models with systemic risk. | E40: **Where the exception is written in the primary AI Act text** The exception for providers of general‑purpose AI (GPAI) models that are released under a free and open‑source licence is set out in the **AI Act itself** in the following provisions: | Provision | Text (excerpt) | What it covers | |-----------|----------------|----------------| | **Article 53(2)** | “The obligations set out in Article 53 shall not apply to providers of AI models that are released under a free and open‑source licence that allows for the access, usage, modification, and distribution of the model, and whose parameters, including the weights, the information on the model architecture, and the information on model usage, are made publicly available, **unless the model is a general‑purpose AI model with systemic risk**.” | This is the core wording that exempts open‑source GPAI providers from the obligations in Article 53(1)(a) and (b) unless the model is deemed to have systemic risk. | | **Article 54(6)** | “The obligations set out in Article 54 shall not apply to providers of AI models that are released under a free and open‑source licence that allows for the access, usage, modification, and distribution of the model, and whose parameters, including the weights, the information on the model architecture, and the information on model usage, are made publicly available, **unless the model is a general‑purpose AI model with systemic risk**.” | This mirrors the same exception for the obligations in Article 54 (e.g., appointing an authorised representative). | These two articles are the only places in the primary regulation where the exception is explicitly written. **Does this match the Service Desk’s summary?** Yes. The Service Desk’s Article 53 page correctly states that: * “Open‑source GPAI providers are exempt from Article 53(1)(a) and (b) **unless the model has systemic risk**.” This is precisely what Article 53(2) says. The Service Desk also notes that the same exception applies to Article 54 obligations, which is reflected in Article 54(6). Therefore, the Service Desk’s summary is consistent with the wording in the primary AI Act regulation. | F40: 0 | H40: 0 | I40: 0 | J40: 3 | K40: 1 | L40: 1 | M40: Correct | N40: Correct, thorough (Art 53(2) verbatim + correct Art 54(6) parallel). Document-level 'miss' on labelled expected source, yet the correct clause was found via other retrieved chunks.
A41: 39 | B41: multi-hop | C41: The Commission's GPAI scope guidelines describe an open-source exemption from Article 53(1)(a)-(b). Which article of the AI Act's own text, as also captured in the Service Desk's Article 53 page, establishes this exemption, and what condition removes it? | D41: Article 53(2) AI Act establishes the exemption for free-and-open-source-licensed GPAI models with publicly available parameters/weights/architecture/usage information; the condition that removes the exemption, per both the primary text and the Service Desk summary, is that the model is classified as a general-purpose AI model with systemic risk — in which case the open-source exemption from documentation obligations (a) and (b) no longer applies. | E41: The exemption is set out in **Article 53(1)(a) and (b) of the AI Act** itself – the same provisions that the Service Desk’s Article 53 page lists. The condition that removes the exemption is that the model **is a general‑purpose AI model with systemic risk**. If the model falls into that category, the exemption does not apply. | F41: 1 | G41: 2 | H41: 0.5 | I41: 1 | J41: 4 | K41: 0.5 | L41: 0.3 | M41: Partial / Incorrect | N41: MAJOR FINDING: misidentifies the exemption as sitting in Art 53(1)(a)/(b) itself, when it is actually Art 53(2) -- directly contradicting the SAME system's correct citation of Art 53(2) in record 38. A clear self-consistency failure on an adjacent question. The 'systemic risk removes exemption' half is correct.
A42: 40 | B42: multi-hop | C42: A provider wants to know whether their chatbot needs both an Article 50(1) 'you are talking to an AI' disclosure and a GDPR Article 13/14 information notice. Do these two obligations serve the same purpose, or are they distinct requirements that could both apply to the same system? | D42: They are distinct and can both apply. Article 50(1) AI Act requires disclosing the fact of interacting with an AI system itself (a transparency-of-AI-nature obligation), while GDPR Articles 13/14 require informing data subjects about the processing of their personal data (identity of controller, purposes, legal basis, retention, rights, and — per Article 13(2)(f)/14(2)(g) — the existence of automated decision-making/profiling under Article 22 and meaningful information about its logic). A chatbot that also processes personal data would need to satisfy both notice regimes, which cover different information. | E42: The two obligations are **distinct** and can both apply to the same system. * **Article 50(1) AI Act** – requires that any AI system that directly interacts with a natural person must inform that person that they are interacting with an AI system (“you are talking to an AI”). This is a specific transparency requirement that applies to the AI system itself. * **GDPR Articles 13/14** – require that data subjects receive information about the processing of their personal data (purpose, legal basis, rights, etc.). This is a separate data‑protection information obligation. The guidance states that the transparency obligation under Article 50(1) “applies without prejudice to Union data protection law” (see context excerpts [3] and [4]). Therefore, the AI‑specific disclosure and the GDPR information notice serve different purposes and can both be required for the same chatbot. | F42: 0 | H42: 0 | I42: 0 | J42: 1 | K42: 1 | L42: 0.5 | M42: Partial | N42: Correct on the top-level distinctness of the two obligations; misses the Art 13(2)(f)/14(2)(g) automated-decision-making notice link that the multi-hop question is really testing. Document-level retrieval miss; thin citation set (n=1).
A44: AVG / TOTAL | F44: =AVERAGE(F2:F42) -> 0.82926829 | H44: =AVERAGE(H2:H42) -> 0.55975122 | I44: =AVERAGE(I2:I42) -> 0.82926829 | J44: =SUM(J2:J42) -> 118 | K44: =AVERAGE(K2:K42) -> 0.95853659 | L44: =AVERAGE(L2:L42) -> 0.7804878
